Workbook
Name BestHits: Calc!$B$13
Name ResultCount: Calc!$B$4
Name ScopeChoices: Calc!$M$2:INDEX(Calc!$M$2:$M$501, MAX(1, COUNTA(Calc!$M$2:$M$501)))
Name ScopeOverride: Calc!$B$15
Name SearchBox: Index!$E$6
Name SearchMode: Index!$B$8
Name SelScope: Index!$B$6
Name ShownCount: Calc!$B$5
Name Slicer_Scope_Group: #N/A
Name TermCount: Calc!$B$12
Name TotalDocs: Calc!$B$8
Name VisibleDocs: Calc!$B$14

Sheet Index
B2: AVS DOCUMENT REPOSITORY
B3: =Calc!$B$11 -> Search and browse the Azure VMware Solution document library • 109 documents indexed • 12 scopes
B5: FILTER BY SCOPE | E5: SEARCH
B6: All
B7: WHEN SEARCHING | E7: Type any words: name, type, scope, keywords or description.
B8: Search all scopes
B9: DOCUMENTS BY SCOPE (summary) | E9: =Calc!$B$9 -> 109 documents found across all scopes
B11: SCOPE | C11: DOCS | E11: DOCUMENT NAME | F11: TYPE | G11: SCOPE | H11: DESCRIPTION
B12: =IFERROR(IF(INDEX(Calc!$M$2:$M$501, 1) = "", "", INDEX(Calc!$M$2:$M$501, 1)), "") -> All | C12: =IF($B12 = "", "", IF($B12 = "All", VisibleDocs, IFERROR(SUMPRODUCT(--(tblDocuments[Scope Group] = $B12) * tblDocuments[Visible]), 0))) -> 109 | E12: =IFERROR(IF($K12 = "", "", IF(INDEX(tblDocuments[Link Out], $K12) = "", INDEX(tblDocuments[Display Name], $K12), HYPERLINK(INDEX(tblDocuments[Link Out], $K12), INDEX(tblDocuments[Display Name], $K12)))), "") -> AVS Platform High Level Design | F12: =IFERROR(IF($K12 = "", "", IF(TRIM(INDEX(tblDocuments[Document Type], $K12) & "") = "", "—", TRIM(INDEX(tblDocuments[Document Type], $K12) & ""))), "") -> HLD | G12: =IFERROR(IF($K12 = "", "", INDEX(tblDocuments[Scope Group], $K12)), "") -> Design | H12: =IFERROR(IF($K12 = "", "", IF(TRIM(INDEX(tblDocuments[Description], $K12) & "") = "", "—", IF(LEN(TRIM(INDEX(tblDocuments[Description], $K12) & "")) > 165, LEFT(TRIM(INDEX(tblDocuments[Description], $K12) & ""), 164) & "…", TRIM(INDEX(tblDocuments[Description], $K12) & "")))), "") -> End-to-end high level design for the Azure VMware Solution private cloud landing zone, covering region selection, SDDC sizing and connectivity. | K12: =IFERROR(IF(1 > ResultCount, "", MATCH(LARGE(tblDocuments[Sort Key], 1), tblDocuments[Sort Key], 0)), "") -> 1
B13: =IFERROR(IF(INDEX(Calc!$M$2:$M$501, 2) = "", "", INDEX(Calc!$M$2:$M$501, 2)), "") -> (Unspecified) | C13: =IF($B13 = "", "", IF($B13 = "All", VisibleDocs, IFERROR(SUMPRODUCT(--(tblDocuments[Scope Group] = $B13) * tblDocuments[Visible]), 0))) -> 1 | E13: =IFERROR(IF($K13 = "", "", IF(INDEX(tblDocuments[Link Out], $K13) = "", INDEX(tblDocuments[Display Name], $K13), HYPERLINK(INDEX(tblDocuments[Link Out], $K13), INDEX(tblDocuments[Display Name], $K13)))), "") -> AVS Private Cloud Low Level Design | F13: =IFERROR(IF($K13 = "", "", IF(TRIM(INDEX(tblDocuments[Document Type], $K13) & "") = "", "—", TRIM(INDEX(tblDocuments[Document Type], $K13) & ""))), "") -> LLD | G13: =IFERROR(IF($K13 = "", "", INDEX(tblDocuments[Scope Group], $K13)), "") -> Design | H13: =IFERROR(IF($K13 = "", "", IF(TRIM(INDEX(tblDocuments[Description], $K13) & "") = "", "—", IF(LEN(TRIM(INDEX(tblDocuments[Description], $K13) & "")) > 165, LEFT(TRIM(INDEX(tblDocuments[Description], $K13) & ""), 164) & "…", TRIM(INDEX(tblDocuments[Description], $K13) & "")))), "") -> Detailed build parameters for the production private cloud: cluster layout, host SKU, management network CIDRs and vCenter configuration. | K13: =IFERROR(IF(2 > ResultCount, "", MATCH(LARGE(tblDocuments[Sort Key], 2), tblDocuments[Sort Key], 0)), "") -> 2
B14: =IFERROR(IF(INDEX(Calc!$M$2:$M$501, 3) = "", "", INDEX(Calc!$M$2:$M$501, 3)), "") -> Backup & DR | C14: =IF($B14 = "", "", IF($B14 = "All", VisibleDocs, IFERROR(SUMPRODUCT(--(tblDocuments[Scope Group] = $B14) * tblDocuments[Visible]), 0))) -> 9 | E14: =IFERROR(IF($K14 = "", "", IF(INDEX(tblDocuments[Link Out], $K14) = "", INDEX(tblDocuments[Display Name], $K14), HYPERLINK(INDEX(tblDocuments[Link Out], $K14), INDEX(tblDocuments[Display Name], $K14)))), "") -> AVS Reference Architecture Overview | F14: =IFERROR(IF($K14 = "", "", IF(TRIM(INDEX(tblDocuments[Document Type], $K14) & "") = "", "—", TRIM(INDEX(tblDocuments[Document Type], $K14) & ""))), "") -> Architecture | G14: =IFERROR(IF($K14 = "", "", INDEX(tblDocuments[Scope Group], $K14)), "") -> Design | H14: =IFERROR(IF($K14 = "", "", IF(TRIM(INDEX(tblDocuments[Description], $K14) & "") = "", "—", IF(LEN(TRIM(INDEX(tblDocuments[Description], $K14) & "")) > 165, LEFT(TRIM(INDEX(tblDocuments[Description], $K14) & ""), 164) & "…", TRIM(INDEX(tblDocuments[Description], $K14) & "")))), "") -> Reference architecture describing how AVS integrates with Azure native services, ExpressRoute Global Reach and on-premises vSphere. | K14: =IFERROR(IF(3 > ResultCount, "", MATCH(LARGE(tblDocuments[Sort Key], 3), tblDocuments[Sort Key], 0)), "") -> 3
B15: =IFERROR(IF(INDEX(Calc!$M$2:$M$501, 4) = "", "", INDEX(Calc!$M$2:$M$501, 4)), "") -> Cost | C15: =IF($B15 = "", "", IF($B15 = "All", VisibleDocs, IFERROR(SUMPRODUCT(--(tblDocuments[Scope Group] = $B15) * tblDocuments[Visible]), 0))) -> 5 | E15: =IFERROR(IF($K15 = "", "", IF(INDEX(tblDocuments[Link Out], $K15) = "", INDEX(tblDocuments[Display Name], $K15), HYPERLINK(INDEX(tblDocuments[Link Out], $K15), INDEX(tblDocuments[Display Name], $K15)))), "") -> AVS Logical Architecture Diagram | F15: =IFERROR(IF($K15 = "", "", IF(TRIM(INDEX(tblDocuments[Document Type], $K15) & "") = "", "—", TRIM(INDEX(tblDocuments[Document Type], $K15) & ""))), "") -> Diagram | G15: =IFERROR(IF($K15 = "", "", INDEX(tblDocuments[Scope Group], $K15)), "") -> Design | H15: =IFERROR(IF($K15 = "", "", IF(TRIM(INDEX(tblDocuments[Description], $K15) & "") = "", "—", IF(LEN(TRIM(INDEX(tblDocuments[Description], $K15) & "")) > 165, LEFT(TRIM(INDEX(tblDocuments[Description], $K15) & ""), 164) & "…", TRIM(INDEX(tblDocuments[Description], $K15) & "")))), "") -> Visio source for the logical architecture diagram used across the programme design authority pack. | K15: =IFERROR(IF(4 > ResultCount, "", MATCH(LARGE(tblDocuments[Sort Key], 4), tblDocuments[Sort Key], 0)), "") -> 4
B16: =IFERROR(IF(INDEX(Calc!$M$2:$M$501, 5) = "", "", INDEX(Calc!$M$2:$M$501, 5)), "") -> Design | C16: =IF($B16 = "", "", IF($B16 = "All", VisibleDocs, IFERROR(SUMPRODUCT(--(tblDocuments[Scope Group] = $B16) * tblDocuments[Visible]), 0))) -> 12 | E16: =IFERROR(IF($K16 = "", "", IF(INDEX(tblDocuments[Link Out], $K16) = "", INDEX(tblDocuments[Display Name], $K16), HYPERLINK(INDEX(tblDocuments[Link Out], $K16), INDEX(tblDocuments[Display Name], $K16)))), "") -> ADR-014 Host SKU Selection AV36P vs AV52 | F16: =IFERROR(IF($K16 = "", "", IF(TRIM(INDEX(tblDocuments[Document Type], $K16) & "") = "", "—", TRIM(INDEX(tblDocuments[Document Type], $K16) & ""))), "") -> Decision Record | G16: =IFERROR(IF($K16 = "", "", INDEX(tblDocuments[Scope Group], $K16)), "") -> Design | H16: =IFERROR(IF($K16 = "", "", IF(TRIM(INDEX(tblDocuments[Description], $K16) & "") = "", "—", IF(LEN(TRIM(INDEX(tblDocuments[Description], $K16) & "")) > 165, LEFT(TRIM(INDEX(tblDocuments[Description], $K16) & ""), 164) & "…", TRIM(INDEX(tblDocuments[Description], $K16) & "")))), "") -> Architecture decision record capturing the comparison and final selection of the AV36P host SKU for the production estate. | K16: =IFERROR(IF(5 > ResultCount, "", MATCH(LARGE(tblDocuments[Sort Key], 5), tblDocuments[Sort Key], 0)), "") -> 5
B17: =IFERROR(IF(INDEX(Calc!$M$2:$M$501, 6) = "", "", INDEX(Calc!$M$2:$M$501, 6)), "") -> Governance | C17: =IF($B17 = "", "", IF($B17 = "All", VisibleDocs, IFERROR(SUMPRODUCT(--(tblDocuments[Scope Group] = $B17) * tblDocuments[Visible]), 0))) -> 7 | E17: =IFERROR(IF($K17 = "", "", IF(INDEX(tblDocuments[Link Out], $K17) = "", INDEX(tblDocuments[Display Name], $K17), HYPERLINK(INDEX(tblDocuments[Link Out], $K17), INDEX(tblDocuments[Display Name], $K17)))), "") -> AVS Sizing and Capacity Assessment | F17: =IFERROR(IF($K17 = "", "", IF(TRIM(INDEX(tblDocuments[Document Type], $K17) & "") = "", "—", TRIM(INDEX(tblDocuments[Document Type], $K17) & ""))), "") -> Assessment | G17: =IFERROR(IF($K17 = "", "", INDEX(tblDocuments[Scope Group], $K17)), "") -> Design | H17: =IFERROR(IF($K17 = "", "", IF(TRIM(INDEX(tblDocuments[Description], $K17) & "") = "", "—", IF(LEN(TRIM(INDEX(tblDocuments[Description], $K17) & "")) > 165, LEFT(TRIM(INDEX(tblDocuments[Description], $K17) & ""), 164) & "…", TRIM(INDEX(tblDocuments[Description], $K17) & "")))), "") -> Capacity model translating the discovered on-premises estate into required AVS node counts, including growth and slack assumptions. | K17: =IFERROR(IF(6 > ResultCount, "", MATCH(LARGE(tblDocuments[Sort Key], 6), tblDocuments[Sort Key], 0)), "") -> 6
B18: =IFERROR(IF(INDEX(Calc!$M$2:$M$501, 7) = "", "", INDEX(Calc!$M$2:$M$501, 7)), "") -> Identity | C18: =IF($B18 = "", "", IF($B18 = "All", VisibleDocs, IFERROR(SUMPRODUCT(--(tblDocuments[Scope Group] = $B18) * tblDocuments[Visible]), 0))) -> 6 | E18: =IFERROR(IF($K18 = "", "", IF(INDEX(tblDocuments[Link Out], $K18) = "", INDEX(tblDocuments[Display Name], $K18), HYPERLINK(INDEX(tblDocuments[Link Out], $K18), INDEX(tblDocuments[Display Name], $K18)))), "") -> Stretched Clusters for AVS Explained | F18: =IFERROR(IF($K18 = "", "", IF(TRIM(INDEX(tblDocuments[Document Type], $K18) & "") = "", "—", TRIM(INDEX(tblDocuments[Document Type], $K18) & ""))), "") -> Whitepaper | G18: =IFERROR(IF($K18 = "", "", INDEX(tblDocuments[Scope Group], $K18)), "") -> Design | H18: =IFERROR(IF($K18 = "", "", IF(TRIM(INDEX(tblDocuments[Description], $K18) & "") = "", "—", IF(LEN(TRIM(INDEX(tblDocuments[Description], $K18) & "")) > 165, LEFT(TRIM(INDEX(tblDocuments[Description], $K18) & ""), 164) & "…", TRIM(INDEX(tblDocuments[Description], $K18) & "")))), "") -> Whitepaper on stretched cluster availability zones in AVS, the SLA implications and when the pattern is appropriate. | K18: =IFERROR(IF(7 > ResultCount, "", MATCH(LARGE(tblDocuments[Sort Key], 7), tblDocuments[Sort Key], 0)), "") -> 7
B19: =IFERROR(IF(INDEX(Calc!$M$2:$M$501, 8) = "", "", INDEX(Calc!$M$2:$M$501, 8)), "") -> Migration | C19: =IF($B19 = "", "", IF($B19 = "All", VisibleDocs, IFERROR(SUMPRODUCT(--(tblDocuments[Scope Group] = $B19) * tblDocuments[Visible]), 0))) -> 15 | E19: =IFERROR(IF($K19 = "", "", IF(INDEX(tblDocuments[Link Out], $K19) = "", INDEX(tblDocuments[Display Name], $K19), HYPERLINK(INDEX(tblDocuments[Link Out], $K19), INDEX(tblDocuments[Display Name], $K19)))), "") -> AVS Landing Zone Accelerator Walkthrough | F19: =IFERROR(IF($K19 = "", "", IF(TRIM(INDEX(tblDocuments[Document Type], $K19) & "") = "", "—", TRIM(INDEX(tblDocuments[Document Type], $K19) & ""))), "") -> Guide | G19: =IFERROR(IF($K19 = "", "", INDEX(tblDocuments[Scope Group], $K19)), "") -> Design | H19: =IFERROR(IF($K19 = "", "", IF(TRIM(INDEX(tblDocuments[Description], $K19) & "") = "", "—", IF(LEN(TRIM(INDEX(tblDocuments[Description], $K19) & "")) > 165, LEFT(TRIM(INDEX(tblDocuments[Description], $K19) & ""), 164) & "…", TRIM(INDEX(tblDocuments[Description], $K19) & "")))), "") -> Walkthrough of the Microsoft AVS landing zone accelerator and the deltas applied for this programme. | K19: =IFERROR(IF(8 > ResultCount, "", MATCH(LARGE(tblDocuments[Sort Key], 8), tblDocuments[Sort Key], 0)), "") -> 8
B20: =IFERROR(IF(INDEX(Calc!$M$2:$M$501, 9) = "", "", INDEX(Calc!$M$2:$M$501, 9)), "") -> Network | C20: =IF($B20 = "", "", IF($B20 = "All", VisibleDocs, IFERROR(SUMPRODUCT(--(tblDocuments[Scope Group] = $B20) * tblDocuments[Visible]), 0))) -> 17 | E20: =IFERROR(IF($K20 = "", "", IF(INDEX(tblDocuments[Link Out], $K20) = "", INDEX(tblDocuments[Display Name], $K20), HYPERLINK(INDEX(tblDocuments[Link Out], $K20), INDEX(tblDocuments[Display Name], $K20)))), "") -> Hybrid Connectivity High Level Design | F20: =IFERROR(IF($K20 = "", "", IF(TRIM(INDEX(tblDocuments[Document Type], $K20) & "") = "", "—", TRIM(INDEX(tblDocuments[Document Type], $K20) & ""))), "") -> HLD | G20: =IFERROR(IF($K20 = "", "", INDEX(tblDocuments[Scope Group], $K20)), "") -> Design | H20: =IFERROR(IF($K20 = "", "", IF(TRIM(INDEX(tblDocuments[Description], $K20) & "") = "", "—", IF(LEN(TRIM(INDEX(tblDocuments[Description], $K20) & "")) > 165, LEFT(TRIM(INDEX(tblDocuments[Description], $K20) & ""), 164) & "…", TRIM(INDEX(tblDocuments[Description], $K20) & "")))), "") -> High level design for hybrid connectivity between on-premises datacentres, Azure regions and the AVS private clouds. | K20: =IFERROR(IF(9 > ResultCount, "", MATCH(LARGE(tblDocuments[Sort Key], 9), tblDocuments[Sort Key], 0)), "") -> 9
B21: =IFERROR(IF(INDEX(Calc!$M$2:$M$501, 10) = "", "", INDEX(Calc!$M$2:$M$501, 10)), "") -> Operations | C21: =IF($B21 = "", "", IF($B21 = "All", VisibleDocs, IFERROR(SUMPRODUCT(--(tblDocuments[Scope Group] = $B21) * tblDocuments[Visible]), 0))) -> 14 | E21: =IFERROR(IF($K21 = "", "", IF(INDEX(tblDocuments[Link Out], $K21) = "", INDEX(tblDocuments[Display Name], $K21), HYPERLINK(INDEX(tblDocuments[Link Out], $K21), INDEX(tblDocuments[Display Name], $K21)))), "") -> Design Document Template | F21: =IFERROR(IF($K21 = "", "", IF(TRIM(INDEX(tblDocuments[Document Type], $K21) & "") = "", "—", TRIM(INDEX(tblDocuments[Document Type], $K21) & ""))), "") -> Template | G21: =IFERROR(IF($K21 = "", "", INDEX(tblDocuments[Scope Group], $K21)), "") -> Design | H21: =IFERROR(IF($K21 = "", "", IF(TRIM(INDEX(tblDocuments[Description], $K21) & "") = "", "—", IF(LEN(TRIM(INDEX(tblDocuments[Description], $K21) & "")) > 165, LEFT(TRIM(INDEX(tblDocuments[Description], $K21) & ""), 164) & "…", TRIM(INDEX(tblDocuments[Description], $K21) & "")))), "") -> Programme standard template for HLD and LLD deliverables including the mandatory design decision and assumption tables. | K21: =IFERROR(IF(10 > ResultCount, "", MATCH(LARGE(tblDocuments[Sort Key], 10), tblDocuments[Sort Key], 0)), "") -> 10
B22: =IFERROR(IF(INDEX(Calc!$M$2:$M$501, 11) = "", "", INDEX(Calc!$M$2:$M$501, 11)), "") -> Security | C22: =IF($B22 = "", "", IF($B22 = "All", VisibleDocs, IFERROR(SUMPRODUCT(--(tblDocuments[Scope Group] = $B22) * tblDocuments[Visible]), 0))) -> 12 | E22: =IFERROR(IF($K22 = "", "", IF(INDEX(tblDocuments[Link Out], $K22) = "", INDEX(tblDocuments[Display Name], $K22), HYPERLINK(INDEX(tblDocuments[Link Out], $K22), INDEX(tblDocuments[Display Name], $K22)))), "") -> AVS Well Architected Review Findings | F22: =IFERROR(IF($K22 = "", "", IF(TRIM(INDEX(tblDocuments[Document Type], $K22) & "") = "", "—", TRIM(INDEX(tblDocuments[Document Type], $K22) & ""))), "") -> Report | G22: =IFERROR(IF($K22 = "", "", INDEX(tblDocuments[Scope Group], $K22)), "") -> Design | H22: =IFERROR(IF($K22 = "", "", IF(TRIM(INDEX(tblDocuments[Description], $K22) & "") = "", "—", IF(LEN(TRIM(INDEX(tblDocuments[Description], $K22) & "")) > 165, LEFT(TRIM(INDEX(tblDocuments[Description], $K22) & ""), 164) & "…", TRIM(INDEX(tblDocuments[Description], $K22) & "")))), "") -> Findings and prioritised recommendations from the Well Architected Framework review of the AVS platform. | K22: =IFERROR(IF(11 > ResultCount, "", MATCH(LARGE(tblDocuments[Sort Key], 11), tblDocuments[Sort Key], 0)), "") -> 11
B23: =IFERROR(IF(INDEX(Calc!$M$2:$M$501, 12) = "", "", INDEX(Calc!$M$2:$M$501, 12)), "") -> Storage | C23: =IF($B23 = "", "", IF($B23 = "All", VisibleDocs, IFERROR(SUMPRODUCT(--(tblDocuments[Scope Group] = $B23) * tblDocuments[Visible]), 0))) -> 6 | E23: =IFERROR(IF($K23 = "", "", IF(INDEX(tblDocuments[Link Out], $K23) = "", INDEX(tblDocuments[Display Name], $K23), HYPERLINK(INDEX(tblDocuments[Link Out], $K23), INDEX(tblDocuments[Display Name], $K23)))), "") -> AVS Migration Strategy and Approach | F23: =IFERROR(IF($K23 = "", "", IF(TRIM(INDEX(tblDocuments[Document Type], $K23) & "") = "", "—", TRIM(INDEX(tblDocuments[Document Type], $K23) & ""))), "") -> Strategy | G23: =IFERROR(IF($K23 = "", "", INDEX(tblDocuments[Scope Group], $K23)), "") -> Migration | H23: =IFERROR(IF($K23 = "", "", IF(TRIM(INDEX(tblDocuments[Description], $K23) & "") = "", "—", IF(LEN(TRIM(INDEX(tblDocuments[Description], $K23) & "")) > 165, LEFT(TRIM(INDEX(tblDocuments[Description], $K23) & ""), 164) & "…", TRIM(INDEX(tblDocuments[Description], $K23) & "")))), "") -> Overall migration strategy covering wave planning, the 6R disposition model and the cutover governance model. | K23: =IFERROR(IF(12 > ResultCount, "", MATCH(LARGE(tblDocuments[Sort Key], 12), tblDocuments[Sort Key], 0)), "") -> 12
B24: =IFERROR(IF(INDEX(Calc!$M$2:$M$501, 13) = "", "", INDEX(Calc!$M$2:$M$501, 13)), "") -> Training | C24: =IF($B24 = "", "", IF($B24 = "All", VisibleDocs, IFERROR(SUMPRODUCT(--(tblDocuments[Scope Group] = $B24) * tblDocuments[Visible]), 0))) -> 5 | E24: =IFERROR(IF($K24 = "", "", IF(INDEX(tblDocuments[Link Out], $K24) = "", INDEX(tblDocuments[Display Name], $K24), HYPERLINK(INDEX(tblDocuments[Link Out], $K24), INDEX(tblDocuments[Display Name], $K24)))), "") -> HCX Bulk Migration Runbook | F24: =IFERROR(IF($K24 = "", "", IF(TRIM(INDEX(tblDocuments[Document Type], $K24) & "") = "", "—", TRIM(INDEX(tblDocuments[Document Type], $K24) & ""))), "") -> Runbook | G24: =IFERROR(IF($K24 = "", "", INDEX(tblDocuments[Scope Group], $K24)), "") -> Migration | H24: =IFERROR(IF($K24 = "", "", IF(TRIM(INDEX(tblDocuments[Description], $K24) & "") = "", "—", IF(LEN(TRIM(INDEX(tblDocuments[Description], $K24) & "")) > 165, LEFT(TRIM(INDEX(tblDocuments[Description], $K24) & ""), 164) & "…", TRIM(INDEX(tblDocuments[Description], $K24) & "")))), "") -> Step by step runbook for executing an HCX bulk migration wave, including pre-checks, execution and post-migration validation. | K24: =IFERROR(IF(13 > ResultCount, "", MATCH(LARGE(tblDocuments[Sort Key], 13), tblDocuments[Sort Key], 0)), "") -> 13
B25: =IFERROR(IF(INDEX(Calc!$M$2:$M$501, 14) = "", "", INDEX(Calc!$M$2:$M$501, 14)), "") | C25: =IF($B25 = "", "", IF($B25 = "All", VisibleDocs, IFERROR(SUMPRODUCT(--(tblDocuments[Scope Group] = $B25) * tblDocuments[Visible]), 0))) | E25: =IFERROR(IF($K25 = "", "", IF(INDEX(tblDocuments[Link Out], $K25) = "", INDEX(tblDocuments[Display Name], $K25), HYPERLINK(INDEX(tblDocuments[Link Out], $K25), INDEX(tblDocuments[Display Name], $K25)))), "") -> HCX vMotion Live Migration Runbook | F25: =IFERROR(IF($K25 = "", "", IF(TRIM(INDEX(tblDocuments[Document Type], $K25) & "") = "", "—", TRIM(INDEX(tblDocuments[Document Type], $K25) & ""))), "") -> Runbook | G25: =IFERROR(IF($K25 = "", "", INDEX(tblDocuments[Scope Group], $K25)), "") -> Migration | H25: =IFERROR(IF($K25 = "", "", IF(TRIM(INDEX(tblDocuments[Description], $K25) & "") = "", "—", IF(LEN(TRIM(INDEX(tblDocuments[Description], $K25) & "")) > 165, LEFT(TRIM(INDEX(tblDocuments[Description], $K25) & ""), 164) & "…", TRIM(INDEX(tblDocuments[Description], $K25) & "")))), "") -> Runbook for zero downtime live migration of tier 1 workloads using HCX vMotion. | K25: =IFERROR(IF(14 > ResultCount, "", MATCH(LARGE(tblDocuments[Sort Key], 14), tblDocuments[Sort Key], 0)), "") -> 14
B26: =IFERROR(IF(INDEX(Calc!$M$2:$M$501, 15) = "", "", INDEX(Calc!$M$2:$M$501, 15)), "") | C26: =IF($B26 = "", "", IF($B26 = "All", VisibleDocs, IFERROR(SUMPRODUCT(--(tblDocuments[Scope Group] = $B26) * tblDocuments[Visible]), 0))) | E26: =IFERROR(IF($K26 = "", "", IF(INDEX(tblDocuments[Link Out], $K26) = "", INDEX(tblDocuments[Display Name], $K26), HYPERLINK(INDEX(tblDocuments[Link Out], $K26), INDEX(tblDocuments[Display Name], $K26)))), "") -> VMware HCX Deployment and Configuration Guide | F26: =IFERROR(IF($K26 = "", "", IF(TRIM(INDEX(tblDocuments[Document Type], $K26) & "") = "", "—", TRIM(INDEX(tblDocuments[Document Type], $K26) & ""))), "") -> Guide | G26: =IFERROR(IF($K26 = "", "", INDEX(tblDocuments[Scope Group], $K26)), "") -> Migration | H26: =IFERROR(IF($K26 = "", "", IF(TRIM(INDEX(tblDocuments[Description], $K26) & "") = "", "—", IF(LEN(TRIM(INDEX(tblDocuments[Description], $K26) & "")) > 165, LEFT(TRIM(INDEX(tblDocuments[Description], $K26) & ""), 164) & "…", TRIM(INDEX(tblDocuments[Description], $K26) & "")))), "") -> Deployment guide for HCX Connector and HCX Cloud Manager, service mesh creation and network extension setup. | K26: =IFERROR(IF(15 > ResultCount, "", MATCH(LARGE(tblDocuments[Sort Key], 15), tblDocuments[Sort Key], 0)), "") -> 15
B27: =IFERROR(IF(INDEX(Calc!$M$2:$M$501, 16) = "", "", INDEX(Calc!$M$2:$M$501, 16)), "") | C27: =IF($B27 = "", "", IF($B27 = "All", VisibleDocs, IFERROR(SUMPRODUCT(--(tblDocuments[Scope Group] = $B27) * tblDocuments[Visible]), 0))) | E27: =IFERROR(IF($K27 = "", "", IF(INDEX(tblDocuments[Link Out], $K27) = "", INDEX(tblDocuments[Display Name], $K27), HYPERLINK(INDEX(tblDocuments[Link Out], $K27), INDEX(tblDocuments[Display Name], $K27)))), "") -> Migration Wave Readiness Checklist | F27: =IFERROR(IF($K27 = "", "", IF(TRIM(INDEX(tblDocuments[Document Type], $K27) & "") = "", "—", TRIM(INDEX(tblDocuments[Document Type], $K27) & ""))), "") -> Checklist | G27: =IFERROR(IF($K27 = "", "", INDEX(tblDocuments[Scope Group], $K27)), "") -> Migration | H27: =IFERROR(IF($K27 = "", "", IF(TRIM(INDEX(tblDocuments[Description], $K27) & "") = "", "—", IF(LEN(TRIM(INDEX(tblDocuments[Description], $K27) & "")) > 165, LEFT(TRIM(INDEX(tblDocuments[Description], $K27) & ""), 164) & "…", TRIM(INDEX(tblDocuments[Description], $K27) & "")))), "") -> Go/no-go checklist completed before each migration wave is authorised to proceed. | K27: =IFERROR(IF(16 > ResultCount, "", MATCH(LARGE(tblDocuments[Sort Key], 16), tblDocuments[Sort Key], 0)), "") -> 16
B28: =IFERROR(IF(INDEX(Calc!$M$2:$M$501, 17) = "", "", INDEX(Calc!$M$2:$M$501, 17)), "") | C28: =IF($B28 = "", "", IF($B28 = "All", VisibleDocs, IFERROR(SUMPRODUCT(--(tblDocuments[Scope Group] = $B28) * tblDocuments[Visible]), 0))) | E28: =IFERROR(IF($K28 = "", "", IF(INDEX(tblDocuments[Link Out], $K28) = "", INDEX(tblDocuments[Display Name], $K28), HYPERLINK(INDEX(tblDocuments[Link Out], $K28), INDEX(tblDocuments[Display Name], $K28)))), "") -> Migration Wave Plan and Schedule | F28: =IFERROR(IF($K28 = "", "", IF(TRIM(INDEX(tblDocuments[Document Type], $K28) & "") = "", "—", TRIM(INDEX(tblDocuments[Document Type], $K28) & ""))), "") -> Plan | G28: =IFERROR(IF($K28 = "", "", INDEX(tblDocuments[Scope Group], $K28)), "") -> Migration | H28: =IFERROR(IF($K28 = "", "", IF(TRIM(INDEX(tblDocuments[Description], $K28) & "") = "", "—", IF(LEN(TRIM(INDEX(tblDocuments[Description], $K28) & "")) > 165, LEFT(TRIM(INDEX(tblDocuments[Description], $K28) & ""), 164) & "…", TRIM(INDEX(tblDocuments[Description], $K28) & "")))), "") -> Master wave plan listing application groupings, target dates, owners and dependencies for all migration waves. | K28: =IFERROR(IF(17 > ResultCount, "", MATCH(LARGE(tblDocuments[Sort Key], 17), tblDocuments[Sort Key], 0)), "") -> 17
B29: =IFERROR(IF(INDEX(Calc!$M$2:$M$501, 18) = "", "", INDEX(Calc!$M$2:$M$501, 18)), "") | C29: =IF($B29 = "", "", IF($B29 = "All", VisibleDocs, IFERROR(SUMPRODUCT(--(tblDocuments[Scope Group] = $B29) * tblDocuments[Visible]), 0))) | E29: =IFERROR(IF($K29 = "", "", IF(INDEX(tblDocuments[Link Out], $K29) = "", INDEX(tblDocuments[Display Name], $K29), HYPERLINK(INDEX(tblDocuments[Link Out], $K29), INDEX(tblDocuments[Display Name], $K29)))), "") -> Azure Migrate Discovery Report | F29: =IFERROR(IF($K29 = "", "", IF(TRIM(INDEX(tblDocuments[Document Type], $K29) & "") = "", "—", TRIM(INDEX(tblDocuments[Document Type], $K29) & ""))), "") -> Assessment | G29: =IFERROR(IF($K29 = "", "", INDEX(tblDocuments[Scope Group], $K29)), "") -> Migration | H29: =IFERROR(IF($K29 = "", "", IF(TRIM(INDEX(tblDocuments[Description], $K29) & "") = "", "—", IF(LEN(TRIM(INDEX(tblDocuments[Description], $K29) & "")) > 165, LEFT(TRIM(INDEX(tblDocuments[Description], $K29) & ""), 164) & "…", TRIM(INDEX(tblDocuments[Description], $K29) & "")))), "") -> Discovery and dependency mapping output from Azure Migrate for the in-scope on-premises estate. | K29: =IFERROR(IF(18 > ResultCount, "", MATCH(LARGE(tblDocuments[Sort Key], 18), tblDocuments[Sort Key], 0)), "") -> 18
B30: =IFERROR(IF(INDEX(Calc!$M$2:$M$501, 19) = "", "", INDEX(Calc!$M$2:$M$501, 19)), "") | C30: =IF($B30 = "", "", IF($B30 = "All", VisibleDocs, IFERROR(SUMPRODUCT(--(tblDocuments[Scope Group] = $B30) * tblDocuments[Visible]), 0))) | E30: =IFERROR(IF($K30 = "", "", IF(INDEX(tblDocuments[Link Out], $K30) = "", INDEX(tblDocuments[Display Name], $K30), HYPERLINK(INDEX(tblDocuments[Link Out], $K30), INDEX(tblDocuments[Display Name], $K30)))), "") -> Application Cutover Runbook Template | F30: =IFERROR(IF($K30 = "", "", IF(TRIM(INDEX(tblDocuments[Document Type], $K30) & "") = "", "—", TRIM(INDEX(tblDocuments[Document Type], $K30) & ""))), "") -> Runbook | G30: =IFERROR(IF($K30 = "", "", INDEX(tblDocuments[Scope Group], $K30)), "") -> Migration | H30: =IFERROR(IF($K30 = "", "", IF(TRIM(INDEX(tblDocuments[Description], $K30) & "") = "", "—", IF(LEN(TRIM(INDEX(tblDocuments[Description], $K30) & "")) > 165, LEFT(TRIM(INDEX(tblDocuments[Description], $K30) & ""), 164) & "…", TRIM(INDEX(tblDocuments[Description], $K30) & "")))), "") -> Reusable cutover runbook template covering freeze, migrate, validate, smoke test and rollback steps. | K30: =IFERROR(IF(19 > ResultCount, "", MATCH(LARGE(tblDocuments[Sort Key], 19), tblDocuments[Sort Key], 0)), "") -> 19
B31: =IFERROR(IF(INDEX(Calc!$M$2:$M$501, 20) = "", "", INDEX(Calc!$M$2:$M$501, 20)), "") | C31: =IF($B31 = "", "", IF($B31 = "All", VisibleDocs, IFERROR(SUMPRODUCT(--(tblDocuments[Scope Group] = $B31) * tblDocuments[Visible]), 0))) | E31: =IFERROR(IF($K31 = "", "", IF(INDEX(tblDocuments[Link Out], $K31) = "", INDEX(tblDocuments[Display Name], $K31), HYPERLINK(INDEX(tblDocuments[Link Out], $K31), INDEX(tblDocuments[Display Name], $K31)))), "") -> Rollback Procedure for Failed Migrations | F31: =IFERROR(IF($K31 = "", "", IF(TRIM(INDEX(tblDocuments[Document Type], $K31) & "") = "", "—", TRIM(INDEX(tblDocuments[Document Type], $K31) & ""))), "") -> SOP | G31: =IFERROR(IF($K31 = "", "", INDEX(tblDocuments[Scope Group], $K31)), "") -> Migration | H31: =IFERROR(IF($K31 = "", "", IF(TRIM(INDEX(tblDocuments[Description], $K31) & "") = "", "—", IF(LEN(TRIM(INDEX(tblDocuments[Description], $K31) & "")) > 165, LEFT(TRIM(INDEX(tblDocuments[Description], $K31) & ""), 164) & "…", TRIM(INDEX(tblDocuments[Description], $K31) & "")))), "") -> Standard operating procedure for rolling a workload back to the source vSphere estate after a failed migration. | K31: =IFERROR(IF(20 > ResultCount, "", MATCH(LARGE(tblDocuments[Sort Key], 20), tblDocuments[Sort Key], 0)), "") -> 20
B32: =IFERROR(IF(INDEX(Calc!$M$2:$M$501, 21) = "", "", INDEX(Calc!$M$2:$M$501, 21)), "") | C32: =IF($B32 = "", "", IF($B32 = "All", VisibleDocs, IFERROR(SUMPRODUCT(--(tblDocuments[Scope Group] = $B32) * tblDocuments[Visible]), 0))) | E32: =IFERROR(IF($K32 = "", "", IF(INDEX(tblDocuments[Link Out], $K32) = "", INDEX(tblDocuments[Display Name], $K32), HYPERLINK(INDEX(tblDocuments[Link Out], $K32), INDEX(tblDocuments[Display Name], $K32)))), "") -> Cold Migration and OVF Import Guide | F32: =IFERROR(IF($K32 = "", "", IF(TRIM(INDEX(tblDocuments[Document Type], $K32) & "") = "", "—", TRIM(INDEX(tblDocuments[Document Type], $K32) & ""))), "") -> Guide | G32: =IFERROR(IF($K32 = "", "", INDEX(tblDocuments[Scope Group], $K32)), "") -> Migration | H32: =IFERROR(IF($K32 = "", "", IF(TRIM(INDEX(tblDocuments[Description], $K32) & "") = "", "—", IF(LEN(TRIM(INDEX(tblDocuments[Description], $K32) & "")) > 165, LEFT(TRIM(INDEX(tblDocuments[Description], $K32) & ""), 164) & "…", TRIM(INDEX(tblDocuments[Description], $K32) & "")))), "") -> Guide for migrating powered-off workloads and appliance imports using cold migration and OVF/OVA import. | K32: =IFERROR(IF(21 > ResultCount, "", MATCH(LARGE(tblDocuments[Sort Key], 21), tblDocuments[Sort Key], 0)), "") -> 21
B33: =IFERROR(IF(INDEX(Calc!$M$2:$M$501, 22) = "", "", INDEX(Calc!$M$2:$M$501, 22)), "") | C33: =IF($B33 = "", "", IF($B33 = "All", VisibleDocs, IFERROR(SUMPRODUCT(--(tblDocuments[Scope Group] = $B33) * tblDocuments[Visible]), 0))) | E33: =IFERROR(IF($K33 = "", "", IF(INDEX(tblDocuments[Link Out], $K33) = "", INDEX(tblDocuments[Display Name], $K33), HYPERLINK(INDEX(tblDocuments[Link Out], $K33), INDEX(tblDocuments[Display Name], $K33)))), "") -> Migration Wave 3 Closure Report | F33: =IFERROR(IF($K33 = "", "", IF(TRIM(INDEX(tblDocuments[Document Type], $K33) & "") = "", "—", TRIM(INDEX(tblDocuments[Document Type], $K33) & ""))), "") -> Report | G33: =IFERROR(IF($K33 = "", "", INDEX(tblDocuments[Scope Group], $K33)), "") -> Migration | H33: =IFERROR(IF($K33 = "", "", IF(TRIM(INDEX(tblDocuments[Description], $K33) & "") = "", "—", IF(LEN(TRIM(INDEX(tblDocuments[Description], $K33) & "")) > 165, LEFT(TRIM(INDEX(tblDocuments[Description], $K33) & ""), 164) & "…", TRIM(INDEX(tblDocuments[Description], $K33) & "")))), "") -> Closure report for wave 3 including migrated workload counts, defects raised and lessons learned. | K33: =IFERROR(IF(22 > ResultCount, "", MATCH(LARGE(tblDocuments[Sort Key], 22), tblDocuments[Sort Key], 0)), "") -> 22
B34: =IFERROR(IF(INDEX(Calc!$M$2:$M$501, 23) = "", "", INDEX(Calc!$M$2:$M$501, 23)), "") | C34: =IF($B34 = "", "", IF($B34 = "All", VisibleDocs, IFERROR(SUMPRODUCT(--(tblDocuments[Scope Group] = $B34) * tblDocuments[Visible]), 0))) | E34: =IFERROR(IF($K34 = "", "", IF(INDEX(tblDocuments[Link Out], $K34) = "", INDEX(tblDocuments[Display Name], $K34), HYPERLINK(INDEX(tblDocuments[Link Out], $K34), INDEX(tblDocuments[Display Name], $K34)))), "") -> Migration FAQ for Application Owners | F34: =IFERROR(IF($K34 = "", "", IF(TRIM(INDEX(tblDocuments[Document Type], $K34) & "") = "", "—", TRIM(INDEX(tblDocuments[Document Type], $K34) & ""))), "") -> FAQ | G34: =IFERROR(IF($K34 = "", "", INDEX(tblDocuments[Scope Group], $K34)), "") -> Migration | H34: =IFERROR(IF($K34 = "", "", IF(TRIM(INDEX(tblDocuments[Description], $K34) & "") = "", "—", IF(LEN(TRIM(INDEX(tblDocuments[Description], $K34) & "")) > 165, LEFT(TRIM(INDEX(tblDocuments[Description], $K34) & ""), 164) & "…", TRIM(INDEX(tblDocuments[Description], $K34) & "")))), "") -> Frequently asked questions aimed at application owners preparing their workloads for migration to AVS. | K34: =IFERROR(IF(23 > ResultCount, "", MATCH(LARGE(tblDocuments[Sort Key], 23), tblDocuments[Sort Key], 0)), "") -> 23
B35: =IFERROR(IF(INDEX(Calc!$M$2:$M$501, 24) = "", "", INDEX(Calc!$M$2:$M$501, 24)), "") | C35: =IF($B35 = "", "", IF($B35 = "All", VisibleDocs, IFERROR(SUMPRODUCT(--(tblDocuments[Scope Group] = $B35) * tblDocuments[Visible]), 0))) | E35: =IFERROR(IF($K35 = "", "", IF(INDEX(tblDocuments[Link Out], $K35) = "", INDEX(tblDocuments[Display Name], $K35), HYPERLINK(INDEX(tblDocuments[Link Out], $K35), INDEX(tblDocuments[Display Name], $K35)))), "") -> Physical to Virtual Server Conversion Guide | F35: =IFERROR(IF($K35 = "", "", IF(TRIM(INDEX(tblDocuments[Document Type], $K35) & "") = "", "—", TRIM(INDEX(tblDocuments[Document Type], $K35) & ""))), "") -> Guide | G35: =IFERROR(IF($K35 = "", "", INDEX(tblDocuments[Scope Group], $K35)), "") -> Migration | H35: =IFERROR(IF($K35 = "", "", IF(TRIM(INDEX(tblDocuments[Description], $K35) & "") = "", "—", IF(LEN(TRIM(INDEX(tblDocuments[Description], $K35) & "")) > 165, LEFT(TRIM(INDEX(tblDocuments[Description], $K35) & ""), 164) & "…", TRIM(INDEX(tblDocuments[Description], $K35) & "")))), "") -> Guide for converting remaining physical servers into virtual machines prior to migration into AVS. | K35: =IFERROR(IF(24 > ResultCount, "", MATCH(LARGE(tblDocuments[Sort Key], 24), tblDocuments[Sort Key], 0)), "") -> 24
E36: =IFERROR(IF($K36 = "", "", IF(INDEX(tblDocuments[Link Out], $K36) = "", INDEX(tblDocuments[Display Name], $K36), HYPERLINK(INDEX(tblDocuments[Link Out], $K36), INDEX(tblDocuments[Display Name], $K36)))), "") -> Post Migration Validation Checklist | F36: =IFERROR(IF($K36 = "", "", IF(TRIM(INDEX(tblDocuments[Document Type], $K36) & "") = "", "—", TRIM(INDEX(tblDocuments[Document Type], $K36) & ""))), "") -> Checklist | G36: =IFERROR(IF($K36 = "", "", INDEX(tblDocuments[Scope Group], $K36)), "") -> Migration | H36: =IFERROR(IF($K36 = "", "", IF(TRIM(INDEX(tblDocuments[Description], $K36) & "") = "", "—", IF(LEN(TRIM(INDEX(tblDocuments[Description], $K36) & "")) > 165, LEFT(TRIM(INDEX(tblDocuments[Description], $K36) & ""), 164) & "…", TRIM(INDEX(tblDocuments[Description], $K36) & "")))), "") -> Validation checklist executed after each workload lands in AVS covering tools, backup, monitoring and performance. | K36: =IFERROR(IF(25 > ResultCount, "", MATCH(LARGE(tblDocuments[Sort Key], 25), tblDocuments[Sort Key], 0)), "") -> 25
B37: This list is a count, not a control — a cell cannot be clicked to filter anything. Use the Scope box above. WANT ONE-CLICK BUTTONS? 1. Open the Repository sheet 2. Click cell A5 — a document row. The Table Design tab must appear in the ribbon; if it does not, you are not inside the table. 3. Table Design ▸ Insert Slicer 4. Tick Scope Group (not Scope) ▸ OK 5. Optional: click the slicer, Ctrl+X, come back here, Ctrl+V — drop it in the empty space below. If Insert ▸ Slicer opens an Existing Connections box instead, the cursor was outside the table — go back to step 2. Pick Scope Group because it is tidied: trimmed, and blanks shown as (Unspecified). This sheet already reacts to the slicer — nothing else to change. A slicer shows scope names only, never counts — Excel has no option for that. The list above fills that gap: its numbers count documents a filter leaves showing, so they follow the slicer live. Sit the slicer beside the list rather than over it. A slicer clears itself in one click — the funnel-with-a-cross icon in its top-right corner. No formula can clear a slicer for you when you start typing. But set WHEN SEARCHING to 'Search all scopes' and a search simply ignores the slicer and the Scope box instead — same result, and the slicer stays put for when you clear the search. | E37: =IFERROR(IF($K37 = "", "", IF(INDEX(tblDocuments[Link Out], $K37) = "", INDEX(tblDocuments[Display Name], $K37), HYPERLINK(INDEX(tblDocuments[Link Out], $K37), INDEX(tblDocuments[Display Name], $K37)))), "") -> NSX-T Network Low Level Design | F37: =IFERROR(IF($K37 = "", "", IF(TRIM(INDEX(tblDocuments[Document Type], $K37) & "") = "", "—", TRIM(INDEX(tblDocuments[Document Type], $K37) & ""))), "") -> LLD | G37: =IFERROR(IF($K37 = "", "", INDEX(tblDocuments[Scope Group], $K37)), "") -> Network | H37: =IFERROR(IF($K37 = "", "", IF(TRIM(INDEX(tblDocuments[Description], $K37) & "") = "", "—", IF(LEN(TRIM(INDEX(tblDocuments[Description], $K37) & "")) > 165, LEFT(TRIM(INDEX(tblDocuments[Description], $K37) & ""), 164) & "…", TRIM(INDEX(tblDocuments[Description], $K37) & "")))), "") -> Low level design for the NSX-T overlay including tier-0 and tier-1 gateway configuration, segments and routing policy. | K37: =IFERROR(IF(26 > ResultCount, "", MATCH(LARGE(tblDocuments[Sort Key], 26), tblDocuments[Sort Key], 0)), "") -> 26
E38: =IFERROR(IF($K38 = "", "", IF(INDEX(tblDocuments[Link Out], $K38) = "", INDEX(tblDocuments[Display Name], $K38), HYPERLINK(INDEX(tblDocuments[Link Out], $K38), INDEX(tblDocuments[Display Name], $K38)))), "") -> NSX-T Segment Provisioning Guide | F38: =IFERROR(IF($K38 = "", "", IF(TRIM(INDEX(tblDocuments[Document Type], $K38) & "") = "", "—", TRIM(INDEX(tblDocuments[Document Type], $K38) & ""))), "") -> Guide | G38: =IFERROR(IF($K38 = "", "", INDEX(tblDocuments[Scope Group], $K38)), "") -> Network | H38: =IFERROR(IF($K38 = "", "", IF(TRIM(INDEX(tblDocuments[Description], $K38) & "") = "", "—", IF(LEN(TRIM(INDEX(tblDocuments[Description], $K38) & "")) > 165, LEFT(TRIM(INDEX(tblDocuments[Description], $K38) & ""), 164) & "…", TRIM(INDEX(tblDocuments[Description], $K38) & "")))), "") -> How to request, provision and document a new NSX-T overlay segment in the AVS private cloud. | K38: =IFERROR(IF(27 > ResultCount, "", MATCH(LARGE(tblDocuments[Sort Key], 27), tblDocuments[Sort Key], 0)), "") -> 27
E39: =IFERROR(IF($K39 = "", "", IF(INDEX(tblDocuments[Link Out], $K39) = "", INDEX(tblDocuments[Display Name], $K39), HYPERLINK(INDEX(tblDocuments[Link Out], $K39), INDEX(tblDocuments[Display Name], $K39)))), "") -> ExpressRoute Global Reach Configuration Runbook | F39: =IFERROR(IF($K39 = "", "", IF(TRIM(INDEX(tblDocuments[Document Type], $K39) & "") = "", "—", TRIM(INDEX(tblDocuments[Document Type], $K39) & ""))), "") -> Runbook | G39: =IFERROR(IF($K39 = "", "", INDEX(tblDocuments[Scope Group], $K39)), "") -> Network | H39: =IFERROR(IF($K39 = "", "", IF(TRIM(INDEX(tblDocuments[Description], $K39) & "") = "", "—", IF(LEN(TRIM(INDEX(tblDocuments[Description], $K39) & "")) > 165, LEFT(TRIM(INDEX(tblDocuments[Description], $K39) & ""), 164) & "…", TRIM(INDEX(tblDocuments[Description], $K39) & "")))), "") -> Runbook for establishing and validating ExpressRoute Global Reach peering between on-premises circuits and AVS. | K39: =IFERROR(IF(28 > ResultCount, "", MATCH(LARGE(tblDocuments[Sort Key], 28), tblDocuments[Sort Key], 0)), "") -> 28
E40: =IFERROR(IF($K40 = "", "", IF(INDEX(tblDocuments[Link Out], $K40) = "", INDEX(tblDocuments[Display Name], $K40), HYPERLINK(INDEX(tblDocuments[Link Out], $K40), INDEX(tblDocuments[Display Name], $K40)))), "") -> AVS Network Architecture and Traffic Flows | F40: =IFERROR(IF($K40 = "", "", IF(TRIM(INDEX(tblDocuments[Document Type], $K40) & "") = "", "—", TRIM(INDEX(tblDocuments[Document Type], $K40) & ""))), "") -> Architecture | G40: =IFERROR(IF($K40 = "", "", INDEX(tblDocuments[Scope Group], $K40)), "") -> Network | H40: =IFERROR(IF($K40 = "", "", IF(TRIM(INDEX(tblDocuments[Description], $K40) & "") = "", "—", IF(LEN(TRIM(INDEX(tblDocuments[Description], $K40) & "")) > 165, LEFT(TRIM(INDEX(tblDocuments[Description], $K40) & ""), 164) & "…", TRIM(INDEX(tblDocuments[Description], $K40) & "")))), "") -> Network architecture describing north-south and east-west traffic flows, inspection points and internet egress options. | K40: =IFERROR(IF(29 > ResultCount, "", MATCH(LARGE(tblDocuments[Sort Key], 29), tblDocuments[Sort Key], 0)), "") -> 29
E41: =IFERROR(IF($K41 = "", "", IF(INDEX(tblDocuments[Link Out], $K41) = "", INDEX(tblDocuments[Display Name], $K41), HYPERLINK(INDEX(tblDocuments[Link Out], $K41), INDEX(tblDocuments[Display Name], $K41)))), "") -> Internet Egress Options for AVS | F41: =IFERROR(IF($K41 = "", "", IF(TRIM(INDEX(tblDocuments[Document Type], $K41) & "") = "", "—", TRIM(INDEX(tblDocuments[Document Type], $K41) & ""))), "") -> Guide | G41: =IFERROR(IF($K41 = "", "", INDEX(tblDocuments[Scope Group], $K41)), "") -> Network | H41: =IFERROR(IF($K41 = "", "", IF(TRIM(INDEX(tblDocuments[Description], $K41) & "") = "", "—", IF(LEN(TRIM(INDEX(tblDocuments[Description], $K41) & "")) > 165, LEFT(TRIM(INDEX(tblDocuments[Description], $K41) & ""), 164) & "…", TRIM(INDEX(tblDocuments[Description], $K41) & "")))), "") -> Comparison of managed SNAT, public IP down to NSX-T edge, and Azure Firewall egress designs with recommendations. | K41: =IFERROR(IF(30 > ResultCount, "", MATCH(LARGE(tblDocuments[Sort Key], 30), tblDocuments[Sort Key], 0)), "") -> 30
E42: =IFERROR(IF($K42 = "", "", IF(INDEX(tblDocuments[Link Out], $K42) = "", INDEX(tblDocuments[Display Name], $K42), HYPERLINK(INDEX(tblDocuments[Link Out], $K42), INDEX(tblDocuments[Display Name], $K42)))), "") -> NSX-T Distributed Firewall Rule Design | F42: =IFERROR(IF($K42 = "", "", IF(TRIM(INDEX(tblDocuments[Document Type], $K42) & "") = "", "—", TRIM(INDEX(tblDocuments[Document Type], $K42) & ""))), "") -> LLD | G42: =IFERROR(IF($K42 = "", "", INDEX(tblDocuments[Scope Group], $K42)), "") -> Network | H42: =IFERROR(IF($K42 = "", "", IF(TRIM(INDEX(tblDocuments[Description], $K42) & "") = "", "—", IF(LEN(TRIM(INDEX(tblDocuments[Description], $K42) & "")) > 165, LEFT(TRIM(INDEX(tblDocuments[Description], $K42) & ""), 164) & "…", TRIM(INDEX(tblDocuments[Description], $K42) & "")))), "") -> Design of the distributed firewall rule model, security groups, tagging strategy and default deny posture. | K42: =IFERROR(IF(31 > ResultCount, "", MATCH(LARGE(tblDocuments[Sort Key], 31), tblDocuments[Sort Key], 0)), "") -> 31
E43: =IFERROR(IF($K43 = "", "", IF(INDEX(tblDocuments[Link Out], $K43) = "", INDEX(tblDocuments[Display Name], $K43), HYPERLINK(INDEX(tblDocuments[Link Out], $K43), INDEX(tblDocuments[Display Name], $K43)))), "") -> NSX-T Load Balancer Configuration Runbook | F43: =IFERROR(IF($K43 = "", "", IF(TRIM(INDEX(tblDocuments[Document Type], $K43) & "") = "", "—", TRIM(INDEX(tblDocuments[Document Type], $K43) & ""))), "") -> Runbook | G43: =IFERROR(IF($K43 = "", "", INDEX(tblDocuments[Scope Group], $K43)), "") -> Network | H43: =IFERROR(IF($K43 = "", "", IF(TRIM(INDEX(tblDocuments[Description], $K43) & "") = "", "—", IF(LEN(TRIM(INDEX(tblDocuments[Description], $K43) & "")) > 165, LEFT(TRIM(INDEX(tblDocuments[Description], $K43) & ""), 164) & "…", TRIM(INDEX(tblDocuments[Description], $K43) & "")))), "") -> Configuring NSX-T virtual servers, server pools, monitors and persistence profiles for application load balancing. | K43: =IFERROR(IF(32 > ResultCount, "", MATCH(LARGE(tblDocuments[Sort Key], 32), tblDocuments[Sort Key], 0)), "") -> 32
...

Sheet Repository
A1: Repository — source of truth
A2: Add, edit or delete rows anywhere in this table. The Index sheet picks up new documents and new scopes automatically. Columns G-I are hidden helper columns maintained by Excel — do not type over them.
A4: Scope | B4: Document Type | C4: Document Name | D4: Document Link | E4: Description | F4: Keywords | G4: Scope Group | H4: Visible | I4: Search Key | J4: Boost Key | K4: Hits | L4: Score | M4: In Scope | N4: Sort Key | O4: Display Name | P4: Link Out
A5: Design | B5: HLD | C5: AVS Platform High Level Design | D5: https://contoso.sharepoint.com/sites/AVSProgram/Shared%20Documents/Design/AVS-Platform-High-Level-Design.docx | E5: End-to-end high level design for the Azure VMware Solution private cloud landing zone, covering region selection, SDDC sizing and connectivity. | F5: AVS, HLD, high level design, landing zone, SDDC, private cloud, architecture | G5: =IF(TRIM(tblDocuments[[#This Row],[Scope]] & "") = "", "(Unspecified)", TRIM(tblDocuments[[#This Row],[Scope]] & "")) -> Design | H5: =SUBTOTAL(103, tblDocuments[[#This Row],[Scope Group]]) -> 1 | I5: =" "&TRIM(SUBSTITUTE(SUBSTITUTE(SUBSTITUTE(SUBSTITUTE(SUBSTITUTE(SUBSTITUTE(SUBSTITUTE(SUBSTITUTE(SUBSTITUTE(SUBSTITUTE(SUBSTITUTE(SUBSTITUTE(SUBSTITUTE(SUBSTITUTE(SUBSTITUTE(SUBSTITUTE(SUBSTITUTE(SUBSTITUTE(SUBSTITUTE(SUBSTITUTE(SUBSTITUTE(SUBSTITUTE(SUBSTITUTE(SUBSTITUTE(SUBSTITUTE(SUBSTITUTE(SUBSTITUTE(SUBSTITUTE(SUBSTITUTE(SUBSTITUTE(SUBSTITUTE(SUBSTITUTE(LOWER(tblDocuments[[#This Row],[Scope]] & " " & tblDocuments[[#This Row],[Document Type]] & " " & tblDocuments[[#This Row],[Document Name]] & " " & tblDocuments[[#This Row],[Description]] & " " & tblDocuments[[#This Row],[Keywords]]),","," "),";"," "),"/"," "),"\"," "),"-"," "),"_"," "),"("," "),")"," "),"["," "),"]"," "),"{"," "),"}"," "),"."," "),":"," "),"'"," "),"|"," "),"+"," "),"&"," "),"*"," "),"?"," "),"~"," "),"#"," "),"!"," "),"@"," "),"<"," "),">"," "),"="," "),CHAR(34)," "),CHAR(9)," "),CHAR(10)," "),CHAR(13)," "),CHAR(160)," "))&" " -> design hld avs platform high level design end to end high level design for the azure vmware solution private cloud landing zone covering region selection sddc sizing and connectivity avs hld high level design landing zone sddc private cloud architecture | J5: =" "&TRIM(SUBSTITUTE(SUBSTITUTE(SUBSTITUTE(SUBSTITUTE(SUBSTITUTE(SUBSTITUTE(SUBSTITUTE(SUBSTITUTE(SUBSTITUTE(SUBSTITUTE(SUBSTITUTE(SUBSTITUTE(SUBSTITUTE(SUBSTITUTE(SUBSTITUTE(SUBSTITUTE(SUBSTITUTE(SUBSTITUTE(SUBSTITUTE(SUBSTITUTE(SUBSTITUTE(SUBSTITUTE(SUBSTITUTE(SUBSTITUTE(SUBSTITUTE(SUBSTITUTE(SUBSTITUTE(SUBSTITUTE(SUBSTITUTE(SUBSTITUTE(SUBSTITUTE(SUBSTITUTE(LOWER(tblDocuments[[#This Row],[Document Name]] & " " & tblDocuments[[#This Row],[Keywords]] & " " & tblDocuments[[#This Row],[Document Type]] & " " & tblDocuments[[#This Row],[Scope]]),","," "),";"," "),"/"," "),"\"," "),"-"," "),"_"," "),"("," "),")"," "),"["," "),"]"," "),"{"," "),"}"," "),"."," "),":"," "),"'"," "),"|"," "),"+"," "),"&"," "),"*"," "),"?"," "),"~"," "),"#"," "),"!"," "),"@"," "),"<"," "),">"," "),"="," "),CHAR(34)," "),CHAR(9)," "),CHAR(10)," "),CHAR(13)," "),CHAR(160)," "))&" " -> avs platform high level design avs hld high level design landing zone sddc private cloud architecture hld design | K5: =(IF(Calc!$D$2 = "", 0, --ISNUMBER(SEARCH(Calc!$D$2, tblDocuments[[#This Row],[Search Key]]))) + IF(Calc!$E$2 = "", 0, --ISNUMBER(SEARCH(Calc!$E$2, tblDocuments[[#This Row],[Search Key]]))) + IF(Calc!$F$2 = "", 0, --ISNUMBER(SEARCH(Calc!$F$2, tblDocuments[[#This Row],[Search Key]]))) + IF(Calc!$G$2 = "", 0, --ISNUMBER(SEARCH(Calc!$G$2, tblDocuments[[#This Row],[Search Key]]))) + IF(Calc!$H$2 = "", 0, --ISNUMBER(SEARCH(Calc!$H$2, tblDocuments[[#This Row],[Search Key]]))) + IF(Calc!$I$2 = "", 0, --ISNUMBER(SEARCH(Calc!$I$2, tblDocuments[[#This Row],[Search Key]]))) + IF(Calc!$J$2 = "", 0, --ISNUMBER(SEARCH(Calc!$J$2, tblDocuments[[#This Row],[Search Key]]))) + IF(Calc!$K$2 = "", 0, --ISNUMBER(SEARCH(Calc!$K$2, tblDocuments[[#This Row],[Search Key]])))) -> 0 | L5: =IF(TermCount < 2, 0, --ISNUMBER(SEARCH(Calc!$B$3, tblDocuments[[#This Row],[Search Key]]))) * 10 + (IF(Calc!$D$2 = "", 0, --ISNUMBER(SEARCH(" " & Calc!$D$2 & " ", tblDocuments[[#This Row],[Boost Key]]))) + IF(Calc!$E$2 = "", 0, --ISNUMBER(SEARCH(" " & Calc!$E$2 & " ", tblDocuments[[#This Row],[Boost Key]]))) + IF(Calc!$F$2 = "", 0, --ISNUMBER(SEARCH(" " & Calc!$F$2 & " ", tblDocuments[[#This Row],[Boost Key]]))) + IF(Calc!$G$2 = "", 0, --ISNUMBER(SEARCH(" " & Calc!$G$2 & " ", tblDocuments[[#This Row],[Boost Key]]))) + IF(Calc!$H$2 = "", 0, --ISNUMBER(SEARCH(" " & Calc!$H$2 & " ", tblDocuments[[#This Row],[Boost Key]]))) + IF(Calc!$I$2 = "", 0, --ISNUMBER(SEARCH(" " & Calc!$I$2 & " ", tblDocuments[[#This Row],[Boost Key]]))) + IF(Calc!$J$2 = "", 0, --ISNUMBER(SEARCH(" " & Calc!$J$2 & " ", tblDocuments[[#This Row],[Boost Key]]))) + IF(Calc!$K$2 = "", 0, --ISNUMBER(SEARCH(" " & Calc!$K$2 & " ", tblDocuments[[#This Row],[Boost Key]])))) * 4 + (IF(Calc!$D$2 = "", 0, --ISNUMBER(SEARCH(Calc!$D$2, tblDocuments[[#This Row],[Boost Key]]))) + IF(Calc!$E$2 = "", 0, --ISNUMBER(SEARCH(Calc!$E$2, tblDocuments[[#This Row],[Boost Key]]))) + IF(Calc!$F$2 = "", 0, --ISNUMBER(SEARCH(Calc!$F$2, tblDocuments[[#This Row],[Boost Key]]))) + IF(Calc!$G$2 = "", 0, --ISNUMBER(SEARCH(Calc!$G$2, tblDocuments[[#This Row],[Boost Key]]))) + IF(Calc!$H$2 = "", 0, --ISNUMBER(SEARCH(Calc!$H$2, tblDocuments[[#This Row],[Boost Key]]))) + IF(Calc!$I$2 = "", 0, --ISNUMBER(SEARCH(Calc!$I$2, tblDocuments[[#This Row],[Boost Key]]))) + IF(Calc!$J$2 = "", 0, --ISNUMBER(SEARCH(Calc!$J$2, tblDocuments[[#This Row],[Boost Key]]))) + IF(Calc!$K$2 = "", 0, --ISNUMBER(SEARCH(Calc!$K$2, tblDocuments[[#This Row],[Boost Key]])))) * 3 + tblDocuments[[#This Row],[Hits]] * 2 -> 0 | M5: =IF(ScopeOverride = 1, 1, tblDocuments[[#This Row],[Visible]] * --(((TRIM(SelScope & "") = "") + (TRIM(SelScope & "") = "All") + (tblDocuments[[#This Row],[Scope Group]] = TRIM(SelScope & ""))) > 0)) -> 1 | N5: =IF(tblDocuments[[#This Row],[In Scope]] * IF(TermCount = 0, 1, IF(BestHits > 0, --(tblDocuments[[#This Row],[Hits]] = BestHits), 0)) = 1, tblDocuments[[#This Row],[Score]] * 2000000 + (2000000 - ROW()), -1) -> 1999995 | O5: =IF(TRIM(tblDocuments[[#This Row],[Document Name]] & "") = "", "(untitled document)", TRIM(tblDocuments[[#This Row],[Document Name]] & "")) & IF(LEFT(LOWER(TRIM(tblDocuments[[#This Row],[Document Link]] & "")), 4) = "http", "", " (no link)") -> AVS Platform High Level Design | P5: =IF(LEFT(LOWER(TRIM(tblDocuments[[#This Row],[Document Link]] & "")), 4) = "http", TRIM(tblDocuments[[#This Row],[Document Link]] & ""), "") -> https://contoso.sharepoint.com/sites/AVSProgram/Shared%20Documents/Design/AVS-Platform-High-Level-Design.docx
A6: Design | B6: LLD | C6: AVS Private Cloud Low Level Design | D6: https://contoso.sharepoint.com/sites/AVSProgram/Shared%20Documents/Design/AVS-Private-Cloud-Low-Level-Design.docx | E6: Detailed build parameters for the production private cloud: cluster layout, host SKU, management network CIDRs and vCenter configuration. | F6: LLD, low level design, build, cluster, AV36, vCenter, SDDC | G6: =IF(TRIM(tblDocuments[[#This Row],[Scope]] & "") = "", "(Unspecified)", TRIM(tblDocuments[[#This Row],[Scope]] & "")) -> Design | H6: =SUBTOTAL(103, tblDocuments[[#This Row],[Scope Group]]) -> 1 | I6: =" "&TRIM(SUBSTITUTE(SUBSTITUTE(SUBSTITUTE(SUBSTITUTE(SUBSTITUTE(SUBSTITUTE(SUBSTITUTE(SUBSTITUTE(SUBSTITUTE(SUBSTITUTE(SUBSTITUTE(SUBSTITUTE(SUBSTITUTE(SUBSTITUTE(SUBSTITUTE(SUBSTITUTE(SUBSTITUTE(SUBSTITUTE(SUBSTITUTE(SUBSTITUTE(SUBSTITUTE(SUBSTITUTE(SUBSTITUTE(SUBSTITUTE(SUBSTITUTE(SUBSTITUTE(SUBSTITUTE(SUBSTITUTE(SUBSTITUTE(SUBSTITUTE(SUBSTITUTE(SUBSTITUTE(LOWER(tblDocuments[[#This Row],[Scope]] & " " & tblDocuments[[#This Row],[Document Type]] & " " & tblDocuments[[#This Row],[Document Name]] & " " & tblDocuments[[#This Row],[Description]] & " " & tblDocuments[[#This Row],[Keywords]]),","," "),";"," "),"/"," "),"\"," "),"-"," "),"_"," "),"("," "),")"," "),"["," "),"]"," "),"{"," "),"}"," "),"."," "),":"," "),"'"," "),"|"," "),"+"," "),"&"," "),"*"," "),"?"," "),"~"," "),"#"," "),"!"," "),"@"," "),"<"," "),">"," "),"="," "),CHAR(34)," "),CHAR(9)," "),CHAR(10)," "),CHAR(13)," "),CHAR(160)," "))&" " -> design lld avs private cloud low level design detailed build parameters for the production private cloud cluster layout host sku management network cidrs and vcenter configuration lld low level design build cluster av36 vcenter sddc | J6: =" "&TRIM(SUBSTITUTE(SUBSTITUTE(SUBSTITUTE(SUBSTITUTE(SUBSTITUTE(SUBSTITUTE(SUBSTITUTE(SUBSTITUTE(SUBSTITUTE(SUBSTITUTE(SUBSTITUTE(SUBSTITUTE(SUBSTITUTE(SUBSTITUTE(SUBSTITUTE(SUBSTITUTE(SUBSTITUTE(SUBSTITUTE(SUBSTITUTE(SUBSTITUTE(SUBSTITUTE(SUBSTITUTE(SUBSTITUTE(SUBSTITUTE(SUBSTITUTE(SUBSTITUTE(SUBSTITUTE(SUBSTITUTE(SUBSTITUTE(SUBSTITUTE(SUBSTITUTE(SUBSTITUTE(LOWER(tblDocuments[[#This Row],[Document Name]] & " " & tblDocuments[[#This Row],[Keywords]] & " " & tblDocuments[[#This Row],[Document Type]] & " " & tblDocuments[[#This Row],[Scope]]),","," "),";"," "),"/"," "),"\"," "),"-"," "),"_"," "),"("," "),")"," "),"["," "),"]"," "),"{"," "),"}"," "),"."," "),":"," "),"'"," "),"|"," "),"+"," "),"&"," "),"*"," "),"?"," "),"~"," "),"#"," "),"!"," "),"@"," "),"<"," "),">"," "),"="," "),CHAR(34)," "),CHAR(9)," "),CHAR(10)," "),CHAR(13)," "),CHAR(160)," "))&" " -> avs private cloud low level design lld low level design build cluster av36 vcenter sddc lld design | K6: =(IF(Calc!$D$2 = "", 0, --ISNUMBER(SEARCH(Calc!$D$2, tblDocuments[[#This Row],[Search Key]]))) + IF(Calc!$E$2 = "", 0, --ISNUMBER(SEARCH(Calc!$E$2, tblDocuments[[#This Row],[Search Key]]))) + IF(Calc!$F$2 = "", 0, --ISNUMBER(SEARCH(Calc!$F$2, tblDocuments[[#This Row],[Search Key]]))) + IF(Calc!$G$2 = "", 0, --ISNUMBER(SEARCH(Calc!$G$2, tblDocuments[[#This Row],[Search Key]]))) + IF(Calc!$H$2 = "", 0, --ISNUMBER(SEARCH(Calc!$H$2, tblDocuments[[#This Row],[Search Key]]))) + IF(Calc!$I$2 = "", 0, --ISNUMBER(SEARCH(Calc!$I$2, tblDocuments[[#This Row],[Search Key]]))) + IF(Calc!$J$2 = "", 0, --ISNUMBER(SEARCH(Calc!$J$2, tblDocuments[[#This Row],[Search Key]]))) + IF(Calc!$K$2 = "", 0, --ISNUMBER(SEARCH(Calc!$K$2, tblDocuments[[#This Row],[Search Key]])))) -> 0 | L6: =IF(TermCount < 2, 0, --ISNUMBER(SEARCH(Calc!$B$3, tblDocuments[[#This Row],[Search Key]]))) * 10 + (IF(Calc!$D$2 = "", 0, --ISNUMBER(SEARCH(" " & Calc!$D$2 & " ", tblDocuments[[#This Row],[Boost Key]]))) + IF(Calc!$E$2 = "", 0, --ISNUMBER(SEARCH(" " & Calc!$E$2 & " ", tblDocuments[[#This Row],[Boost Key]]))) + IF(Calc!$F$2 = "", 0, --ISNUMBER(SEARCH(" " & Calc!$F$2 & " ", tblDocuments[[#This Row],[Boost Key]]))) + IF(Calc!$G$2 = "", 0, --ISNUMBER(SEARCH(" " & Calc!$G$2 & " ", tblDocuments[[#This Row],[Boost Key]]))) + IF(Calc!$H$2 = "", 0, --ISNUMBER(SEARCH(" " & Calc!$H$2 & " ", tblDocuments[[#This Row],[Boost Key]]))) + IF(Calc!$I$2 = "", 0, --ISNUMBER(SEARCH(" " & Calc!$I$2 & " ", tblDocuments[[#This Row],[Boost Key]]))) + IF(Calc!$J$2 = "", 0, --ISNUMBER(SEARCH(" " & Calc!$J$2 & " ", tblDocuments[[#This Row],[Boost Key]]))) + IF(Calc!$K$2 = "", 0, --ISNUMBER(SEARCH(" " & Calc!$K$2 & " ", tblDocuments[[#This Row],[Boost Key]])))) * 4 + (IF(Calc!$D$2 = "", 0, --ISNUMBER(SEARCH(Calc!$D$2, tblDocuments[[#This Row],[Boost Key]]))) + IF(Calc!$E$2 = "", 0, --ISNUMBER(SEARCH(Calc!$E$2, tblDocuments[[#This Row],[Boost Key]]))) + IF(Calc!$F$2 = "", 0, --ISNUMBER(SEARCH(Calc!$F$2, tblDocuments[[#This Row],[Boost Key]]))) + IF(Calc!$G$2 = "", 0, --ISNUMBER(SEARCH(Calc!$G$2, tblDocuments[[#This Row],[Boost Key]]))) + IF(Calc!$H$2 = "", 0, --ISNUMBER(SEARCH(Calc!$H$2, tblDocuments[[#This Row],[Boost Key]]))) + IF(Calc!$I$2 = "", 0, --ISNUMBER(SEARCH(Calc!$I$2, tblDocuments[[#This Row],[Boost Key]]))) + IF(Calc!$J$2 = "", 0, --ISNUMBER(SEARCH(Calc!$J$2, tblDocuments[[#This Row],[Boost Key]]))) + IF(Calc!$K$2 = "", 0, --ISNUMBER(SEARCH(Calc!$K$2, tblDocuments[[#This Row],[Boost Key]])))) * 3 + tblDocuments[[#This Row],[Hits]] * 2 -> 0 | M6: =IF(ScopeOverride = 1, 1, tblDocuments[[#This Row],[Visible]] * --(((TRIM(SelScope & "") = "") + (TRIM(SelScope & "") = "All") + (tblDocuments[[#This Row],[Scope Group]] = TRIM(SelScope & ""))) > 0)) -> 1 | N6: =IF(tblDocuments[[#This Row],[In Scope]] * IF(TermCount = 0, 1, IF(BestHits > 0, --(tblDocuments[[#This Row],[Hits]] = BestHits), 0)) = 1, tblDocuments[[#This Row],[Score]] * 2000000 + (2000000 - ROW()), -1) -> 1999994 | O6: =IF(TRIM(tblDocuments[[#This Row],[Document Name]] & "") = "", "(untitled document)", TRIM(tblDocuments[[#This Row],[Document Name]] & "")) & IF(LEFT(LOWER(TRIM(tblDocuments[[#This Row],[Document Link]] & "")), 4) = "http", "", " (no link)") -> AVS Private Cloud Low Level Design | P6: =IF(LEFT(LOWER(TRIM(tblDocuments[[#This Row],[Document Link]] & "")), 4) = "http", TRIM(tblDocuments[[#This Row],[Document Link]] & ""), "") -> https://contoso.sharepoint.com/sites/AVSProgram/Shared%20Documents/Design/AVS-Private-Cloud-Low-Level-Design.docx
